2020-10-17 11:07:12,846	INFO services.py:1164 -- View the Ray dashboard at [1m[32mhttp://127.0.0.1:8265[39m[22m
Traceback (most recent call last):
  File "experiment_s_p.py", line 165, in <module>
    res = ray.get(futures)
  File "/home/akanji/miniconda3/envs/seldnian-pre/lib/python3.8/site-packages/ray/worker.py", line 1428, in get
    raise value.as_instanceof_cause()
ray.exceptions.RayTaskError(MemoryError): [36mray::run_experiment_p()[39m (pid=17737, ip=10.128.0.24)
  File "python/ray/_raylet.pyx", line 484, in ray._raylet.execute_task
  File "experiment_s_p.py", line 60, in run_experiment_p
    X_test, y_test, _ = make_synthetic(n*10000, exp['D'], *exp['tprs'], A_idx=A_idx)
  File "/home/akanji/seldonian-fairness/synthetic.py", line 16, in make_synthetic
    X = np.random.default_rng(0).random((N, D))
  File "_generator.pyx", line 208, in numpy.random._generator.Generator.random
  File "_common.pyx", line 270, in numpy.random._common.double_fill
MemoryError: Unable to allocate 144. GiB for an array with shape (3856620420, 5) and data type float64
