2020-10-17 23:10:06,587	INFO services.py:1164 -- View the Ray dashboard at [1m[32mhttp://127.0.0.1:8265[39m[22m
Traceback (most recent call last):
  File "experiment_s_p.py", line 165, in <module>
    res = ray.get(futures)
  File "/home/akanji/miniconda3/envs/seldnian-pre/lib/python3.8/site-packages/ray/worker.py", line 1428, in get
    raise value.as_instanceof_cause()
ray.exceptions.RayTaskError(ValueError): [36mray::run_experiment_p()[39m (pid=35093, ip=10.128.0.3)
  File "python/ray/_raylet.pyx", line 484, in ray._raylet.execute_task
  File "experiment_s_p.py", line 77, in run_experiment_p
    est = SeldonianAlgorithmLogRegCMAES(X, y, test_size=exp['test_size'],
  File "/home/akanji/seldonian-fairness/seldonian.py", line 32, in __init__
    if abs(self.safetyTest(thet, predict=True, ub=False) -
  File "/home/akanji/seldonian-fairness/seldonian.py", line 52, in safetyTest
    ghat_val = g_hat['fn'](X_test, y_test, y_preds, g_hat['delta'], self.X_s.shape[0],
  File "/home/akanji/seldonian-fairness/objectives.py", line 22, in tpr_ab
    bound = abs(ttest_bounds(tp_b, delta, n, predict=predict) - ttest_bounds(tp_a, delta, n, predict=predict))
  File "/home/akanji/seldonian-fairness/bounds.py", line 123, in ttest_bounds
    raise ValueError(f"`samples` should be a vector (1-D array). Got shape: {samples.shape}")
ValueError: `samples` should be a vector (1-D array). Got shape: (3726, 3726)
